User belongs to experiment group 'ShowPlayIcon - start'
User belongs to experiment group 'ShowExtensionSurveyPrompt - enabled'
User belongs to experiment group 'DebugAdapterFactory - experiment'
User belongs to experiment group 'PtvsdWheels37 - experiment'
User belongs to experiment group 'UseTerminalToGetActivatedEnvVars - control'
User belongs to experiment group 'LocalZMQKernel - control'
User belongs to experiment group 'CollectLSRequestTiming - control'
User belongs to experiment group 'CollectNodeLSRequestTiming - experiment'
User belongs to experiment group 'EnableIPyWidgets - experiment'
User belongs to experiment group 'DeprecatePythonPath - control'
User belongs to experiment group 'RunByLine - control'
User belongs to experiment group 'CustomEditorSupport - control'
> conda --version
> pyenv root
> python3.7 ~/.vscode/extensions/ms-python.python-2020.9.111407/pythonFiles/pyvsc-run-isolated.py -c "import sys;print(sys.executable)"
> python3.6 ~/.vscode/extensions/ms-python.python-2020.9.111407/pythonFiles/pyvsc-run-isolated.py -c "import sys;print(sys.executable)"
> python3 ~/.vscode/extensions/ms-python.python-2020.9.111407/pythonFiles/pyvsc-run-isolated.py -c "import sys;print(sys.executable)"
> python2 ~/.vscode/extensions/ms-python.python-2020.9.111407/pythonFiles/pyvsc-run-isolated.py -c "import sys;print(sys.executable)"
> python ~/.vscode/extensions/ms-python.python-2020.9.111407/pythonFiles/pyvsc-run-isolated.py -c "import sys;print(sys.executable)"
> python ~/.vscode/extensions/ms-python.python-2020.9.111407/pythonFiles/pyvsc-run-isolated.py -c "import sys;print(sys.executable)"
> conda info --json
> python ~/.vscode/extensions/ms-python.python-2020.9.111407/pythonFiles/pyvsc-run-isolated.py -c "import sys;print(sys.executable)"
> python ~/.vscode/extensions/ms-python.python-2020.9.111407/pythonFiles/pyvsc-run-isolated.py -c "import sys;print(sys.executable)"
Error 2020-10-01 22:35:17: Failed to check if file needs to be fixed [EntryNotFound (FileSystemError): Unable to read file '/root/.config/Code/User/settings.json' (EntryNotFound (FileSystemError): Error: ENOENT: no such file or directory, open '/root/.config/Code/User/settings.json')
	at _handleError (/usr/share/code/resources/app/out/vs/workbench/services/extensions/node/extensionHostProcess.js:706:74)
	at processTicksAndRejections (internal/process/task_queues.js:94:5)
	at async y.readText (/root/.vscode/extensions/ms-python.python-2020.9.111407/out/client/extension.js:1:498595)
	at async p.doesFileNeedToBeFixed (/root/.vscode/extensions/ms-python.python-2020.9.111407/out/client/extension.js:56:960982)
	at async /root/.vscode/extensions/ms-python.python-2020.9.111407/out/client/extension.js:56:960109
	at async Promise.all (index 0)
	at async p.getFilesToBeFixed (/root/.vscode/extensions/ms-python.python-2020.9.111407/out/client/extension.js:56:960055)
	at async p.updateTestSettings (/root/.vscode/extensions/ms-python.python-2020.9.111407/out/client/extension.js:56:959682)] {
  code: 'FileNotFound',
  name: 'EntryNotFound (FileSystemError)'
}
Error 2020-10-01 22:35:17: Failed to check if file needs to be fixed [EntryNotFound (FileSystemError): Unable to read file '/home/petot/Documents/django-fundamentals/django3/9.model-database/.vscode/settings.json' (EntryNotFound (FileSystemError): Error: ENOENT: no such file or directory, open '/home/petot/Documents/django-fundamentals/django3/9.model-database/.vscode/settings.json')
	at _handleError (/usr/share/code/resources/app/out/vs/workbench/services/extensions/node/extensionHostProcess.js:706:74)
	at processTicksAndRejections (internal/process/task_queues.js:94:5)
	at async y.readText (/root/.vscode/extensions/ms-python.python-2020.9.111407/out/client/extension.js:1:498595)
	at async p.doesFileNeedToBeFixed (/root/.vscode/extensions/ms-python.python-2020.9.111407/out/client/extension.js:56:960982)
	at async /root/.vscode/extensions/ms-python.python-2020.9.111407/out/client/extension.js:56:960109
	at async Promise.all (index 1)
	at async p.getFilesToBeFixed (/root/.vscode/extensions/ms-python.python-2020.9.111407/out/client/extension.js:56:960055)
	at async p.updateTestSettings (/root/.vscode/extensions/ms-python.python-2020.9.111407/out/client/extension.js:56:959682)] {
  code: 'FileNotFound',
  name: 'EntryNotFound (FileSystemError)'
}
Starting Jedi Python language engine.
Python interpreter path: ./env/bin/python3
> /home/petot/Documents/django-fundamentals/django3/9.model-database/env/bin/python3 ~/.vscode/extensions/ms-python.python-2020.9.111407/pythonFiles/pyvsc-run-isolated.py pylint --disable=all --enable=F,unreachable,duplicate-key,unnecessary-semicolon,global-variable-not-assigned,unused-variable,unused-wildcard-import,binary-op-exception,bad-format-string,anomalous-backslash-in-string,bad-open-mode,E0001,E0011,E0012,E0100,E0101,E0102,E0103,E0104,E0105,E0107,E0108,E0110,E0111,E0112,E0113,E0114,E0115,E0116,E0117,E0118,E0202,E0203,E0211,E0213,E0236,E0237,E0238,E0239,E0240,E0241,E0301,E0302,E0303,E0401,E0402,E0601,E0602,E0603,E0604,E0611,E0632,E0633,E0701,E0702,E0703,E0704,E0710,E0711,E0712,E1003,E1101,E1102,E1111,E1120,E1121,E1123,E1124,E1125,E1126,E1127,E1128,E1129,E1130,E1131,E1132,E1133,E1134,E1135,E1136,E1137,E1138,E1139,E1200,E1201,E1205,E1206,E1300,E1301,E1302,E1303,E1304,E1305,E1306,E1310,E1700,E1701 --msg-template='{line},{column},{category},{symbol}:{msg}' --reports=n --output-format=text /home/petot/Documents/django-fundamentals/django3/9.model-database/myweb/myweb/settings.py
cwd: /home/petot/Documents/django-fundamentals/django3/9.model-database
> /home/petot/Documents/django-fundamentals/django3/9.model-database/env/bin/python3 ~/.vscode/extensions/ms-python.python-2020.9.111407/pythonFiles/pyvsc-run-isolated.py pylint --disable=all --enable=F,unreachable,duplicate-key,unnecessary-semicolon,global-variable-not-assigned,unused-variable,unused-wildcard-import,binary-op-exception,bad-format-string,anomalous-backslash-in-string,bad-open-mode,E0001,E0011,E0012,E0100,E0101,E0102,E0103,E0104,E0105,E0107,E0108,E0110,E0111,E0112,E0113,E0114,E0115,E0116,E0117,E0118,E0202,E0203,E0211,E0213,E0236,E0237,E0238,E0239,E0240,E0241,E0301,E0302,E0303,E0401,E0402,E0601,E0602,E0603,E0604,E0611,E0632,E0633,E0701,E0702,E0703,E0704,E0710,E0711,E0712,E1003,E1101,E1102,E1111,E1120,E1121,E1123,E1124,E1125,E1126,E1127,E1128,E1129,E1130,E1131,E1132,E1133,E1134,E1135,E1136,E1137,E1138,E1139,E1200,E1201,E1205,E1206,E1300,E1301,E1302,E1303,E1304,E1305,E1306,E1310,E1700,E1701 --msg-template='{line},{column},{category},{symbol}:{msg}' --reports=n --output-format=text /home/petot/Documents/django-fundamentals/django3/9.model-database/myweb/myweb/settings.py
cwd: /home/petot/Documents/django-fundamentals/django3/9.model-database
> /home/petot/Documents/django-fundamentals/django3/9.model-database/env/bin/python3 ~/.vscode/extensions/ms-python.python-2020.9.111407/pythonFiles/pyvsc-run-isolated.py -c "import pylint"
> /home/petot/Documents/django-fundamentals/django3/9.model-database/env/bin/python3 ~/.vscode/extensions/ms-python.python-2020.9.111407/pythonFiles/pyvsc-run-isolated.py -c "import pylint"
> /home/petot/Documents/django-fundamentals/django3/9.model-database/env/bin/python3 ~/.vscode/extensions/ms-python.python-2020.9.111407/pythonFiles/pyvsc-run-isolated.py -c "import pylint"
> /home/petot/Documents/django-fundamentals/django3/9.model-database/env/bin/python3 ~/.vscode/extensions/ms-python.python-2020.9.111407/pythonFiles/pyvsc-run-isolated.py -c "import pylint"

Linter 'pylint' is not installed. Please install it or select another linter".
Error: Module 'pylint' not installed.
> conda --version
